Traceback (most recent call last):
  File "/Users/spencerdearman/ml-cs/final-project-kanchan-spencer/.venv/lib/python3.11/site-packages/nbclient/client.py", line 782, in _async_poll_for_reply
    msg = await ensure_async(self.kc.shell_channel.get_msg(timeout=new_timeout))
          ^^^^^^^^^^^^^^^^^^^^^^^^^^^^^^^^^^^^^^^^^^^^^^^^^^^^^^^^^^^^^^^^^^^^^^
  File "/Users/spencerdearman/ml-cs/final-project-kanchan-spencer/.venv/lib/python3.11/site-packages/jupyter_core/utils/__init__.py", line 198, in ensure_async
    result = await obj
             ^^^^^^^^^
  File "/Users/spencerdearman/ml-cs/final-project-kanchan-spencer/.venv/lib/python3.11/site-packages/jupyter_client/channels.py", line 313, in get_msg
    raise Empty
_queue.Empty

During handling of the above exception, another exception occurred:

Traceback (most recent call last):
  File "/Users/spencerdearman/ml-cs/final-project-kanchan-spencer/.venv/lib/python3.11/site-packages/jupyter_cache/executors/utils.py", line 58, in single_nb_execution
    executenb(
  File "/Users/spencerdearman/ml-cs/final-project-kanchan-spencer/.venv/lib/python3.11/site-packages/nbclient/client.py", line 1314, in execute
    return NotebookClient(nb=nb, resources=resources, km=km, **kwargs).execute()
           ^^^^^^^^^^^^^^^^^^^^^^^^^^^^^^^^^^^^^^^^^^^^^^^^^^^^^^^^^^^^^^^^^^^^^
  File "/Users/spencerdearman/ml-cs/final-project-kanchan-spencer/.venv/lib/python3.11/site-packages/jupyter_core/utils/__init__.py", line 165, in wrapped
    return loop.run_until_complete(inner)
           ^^^^^^^^^^^^^^^^^^^^^^^^^^^^^^
  File "/opt/homebrew/Cellar/python@3.11/3.11.10/Frameworks/Python.framework/Versions/3.11/lib/python3.11/asyncio/base_events.py", line 654, in run_until_complete
    return future.result()
           ^^^^^^^^^^^^^^^
  File "/Users/spencerdearman/ml-cs/final-project-kanchan-spencer/.venv/lib/python3.11/site-packages/nbclient/client.py", line 709, in async_execute
    await self.async_execute_cell(
  File "/Users/spencerdearman/ml-cs/final-project-kanchan-spencer/.venv/lib/python3.11/site-packages/nbclient/client.py", line 1005, in async_execute_cell
    exec_reply = await self.task_poll_for_reply
                 ^^^^^^^^^^^^^^^^^^^^^^^^^^^^^^
  File "/Users/spencerdearman/ml-cs/final-project-kanchan-spencer/.venv/lib/python3.11/site-packages/nbclient/client.py", line 806, in _async_poll_for_reply
    error_on_timeout_execute_reply = await self._async_handle_timeout(timeout, cell)
                                     ^^^^^^^^^^^^^^^^^^^^^^^^^^^^^^^^^^^^^^^^^^^^^^^
  File "/Users/spencerdearman/ml-cs/final-project-kanchan-spencer/.venv/lib/python3.11/site-packages/nbclient/client.py", line 856, in _async_handle_timeout
    raise CellTimeoutError.error_from_timeout_and_cell(
nbclient.exceptions.CellTimeoutError: A cell timed out while it was being executed, after 30 seconds.
The message was: Cell execution timed out.
Here is a preview of the cell contents:
-------------------
["class_names = ['Benign', 'FTP-BruteForce', 'SSH-Bruteforce']  # Adjust this based on the dataset", "X = brute_force_2017_df.drop(columns=['Label'])", "y = brute_force_2017_df['Label']", '', 'report_2017, best_model_2017 = run_logistic_regression(X, y, class_names)']
...
['report_2018 = predict_on_new_data(best_model_2017, X_2018, y_2018, class_names)', 'print("2018 Classification Report:\\n", report_2018)', '', "metrics_df = collect_metrics(report_2018, 'Brute Force', 'Logistic Regression')", 'metrics_list.append(metrics_df)']
-------------------

